<?xml version="1.0" encoding="utf-8"?>
<!-- This URDF was automatically created by SolidWorks to URDF Exporter! Originally created by Stephen Brawner (brawner@gmail.com) 
     Commit Version: 1.6.0-4-g7f85cfe  Build Version: 1.6.7995.38578
     For more information, please see http://wiki.ros.org/sw_urdf_exporter -->
<robot
  name="agv_gaz">
  <link
    name="base_link">
    <inertial>
      <origin
        xyz="-0.0012409 0.0016043 0.060034"
        rpy="0 0 0" />
      <mass
        value="1.8664" />
      <inertia
        ixx="0.0067583"
        ixy="-3.7474E-11"
        ixz="-1.025E-09"
        iyy="0.031534"
        iyz="0.00011544"
        izz="0.035833" />
    </inertial>
    <visual>
      <origin
        xyz="0 0 0"
        rpy="0 0 0" />
      <geometry>
        <mesh
          filename="package://agv_gaz/meshes/base_link.STL" />
      </geometry>
      <material
        name="">
        <color
          rgba="0.79216 0.81961 0.93333 1" />
      </material>
    </visual>
    <collision>
      <origin
        xyz="0 0 0"
        rpy="0 0 0" />
      <geometry>
        <mesh
          filename="package://agv_gaz/meshes/base_link.STL" />
      </geometry>
    </collision>
  </link>
  <link
    name="L_wheel">
    <inertial>
      <origin
        xyz="0 -5.5511E-17 0.002"
        rpy="0 0 0" />
      <mass
        value="0.16325" />
      <inertia
        ixx="0.00026072"
        ixy="-6.7763E-21"
        ixz="-4.4469E-20"
        iyy="0.00026072"
        iyz="1.0376E-20"
        izz="0.00051794" />
    </inertial>
    <visual>
      <origin
        xyz="0 0 0"
        rpy="0 0 0" />
      <geometry>
        <mesh
          filename="package://agv_gaz/meshes/L_wheel.STL" />
      </geometry>
      <material
        name="">
        <color
          rgba="0.79216 0.81961 0.93333 1" />
      </material>
    </visual>
    <collision>
      <origin
        xyz="0 0 0"
        rpy="0 0 0" />
      <geometry>
        <mesh
          filename="package://agv_gaz/meshes/L_wheel.STL" />
      </geometry>
    </collision>
  </link>
  <joint
    name="L_wheel_joint"
    type="continuous">
    <origin
      xyz="-0.1875 0.16378 -0.040408"
      rpy="-1.5976 0 0" />
    <parent
      link="base_link" />
    <child
      link="L_wheel" />
    <axis
      xyz="0 0 1" />
    <limit
      effort="100"
      velocity="100" />
    <dynamics
      damping="0"
      friction="0.01" />
  </joint>
  <link
    name="R_wheel">
    <inertial>
      <origin
        xyz="0 -1.1102E-16 -0.002"
        rpy="0 0 0" />
      <mass
        value="0.16325" />
      <inertia
        ixx="0.00026072"
        ixy="0"
        ixz="1.9821E-19"
        iyy="0.00026072"
        iyz="-2.8587E-21"
        izz="0.00051794" />
    </inertial>
    <visual>
      <origin
        xyz="0 0 0"
        rpy="0 0 0" />
      <geometry>
        <mesh
          filename="package://agv_gaz/meshes/R_wheel.STL" />
      </geometry>
      <material
        name="">
        <color
          rgba="0.79216 0.81961 0.93333 1" />
      </material>
    </visual>
    <collision>
      <origin
        xyz="0 0 0"
        rpy="0 0 0" />
      <geometry>
        <mesh
          filename="package://agv_gaz/meshes/R_wheel.STL" />
      </geometry>
    </collision>
  </link>
  <joint
    name="R_wheel_joint"
    type="continuous">
    <origin
      xyz="-0.1875 -0.16956 -0.031463"
      rpy="-1.5976 0 0" />
    <parent
      link="base_link" />
    <child
      link="R_wheel" />
    <axis
      xyz="0 0 1" />
    <limit
      effort="100"
      velocity="100" />
    <dynamics
      damping="0"
      friction="0.01" />
  </joint>
  <link
    name="castercase_wheel">
    <inertial>
      <origin
        xyz="5.1987E-06 0.0023604 0.046092"
        rpy="0 0 0" />
      <mass
        value="0.026409" />
      <inertia
        ixx="5.6297E-06"
        ixy="6.9832E-10"
        ixz="-2.0764E-09"
        iyy="5.8585E-06"
        iyz="-8.6931E-07"
        izz="6.9199E-06" />
    </inertial>
    <visual>
      <origin
        xyz="0 0 0"
        rpy="0 0 0" />
      <geometry>
        <mesh
          filename="package://agv_gaz/meshes/castercase_wheel.STL" />
      </geometry>
      <material
        name="">
        <color
          rgba="0.50196 0.50196 0.50196 1" />
      </material>
    </visual>
    <collision>
      <origin
        xyz="0 0 0"
        rpy="0 0 0" />
      <geometry>
        <mesh
          filename="package://agv_gaz/meshes/castercase_wheel.STL" />
      </geometry>
    </collision>
  </link>
  <joint
    name="castercase_wheel_joint"
    type="continuous">
    <origin
      xyz="0.315 -0.00026826 -0.0099964"
      rpy="-3.1416 0.026829 1.5708" />
    <parent
      link="base_link" />
    <child
      link="castercase_wheel" />
    <axis
      xyz="0 0 1" />
    <limit
      effort="100"
      velocity="100" />
    <dynamics
      damping="0"
      friction="0.01" />
  </joint>
  <link
    name="wheel">
    <inertial>
      <origin
        xyz="0 0 0"
        rpy="0 0 0" />
      <mass
        value="0.047294" />
      <inertia
        ixx="9.5074E-06"
        ixy="6.3527E-22"
        ixz="3.6396E-22"
        iyy="9.5074E-06"
        iyz="7.2792E-23"
        izz="1.4188E-05" />
    </inertial>
    <visual>
      <origin
        xyz="0 0 0"
        rpy="0 0 0" />
      <geometry>
        <mesh
          filename="package://agv_gaz/meshes/wheel.STL" />
      </geometry>
      <material
        name="">
        <color
          rgba="0.29412 0.29412 0.29412 1" />
      </material>
    </visual>
    <collision>
      <origin
        xyz="0 0 0"
        rpy="0 0 0" />
      <geometry>
        <mesh
          filename="package://agv_gaz/meshes/wheel.STL" />
      </geometry>
    </collision>
  </link>
  <joint
    name="wheel_joint"
    type="continuous">
    <origin
      xyz="6.3462E-05 0.023 0.08484"
      rpy="1.5708 0 1.568" />
    <parent
      link="castercase_wheel" />
    <child
      link="wheel" />
    <axis
      xyz="0 0 1" />
    <limit
      effort="100"
      velocity="100" />
    <dynamics
      damping="0"
      friction="0.01" />
  </joint>
</robot>